2020-03-03T11:48:17|ERROR|SyncreadoutTriggerJoystickCounterMeasurement|SyncreadoutTriggerJoystickCounterMeasurement Failed to update figure1: list index out of range. ['Traceback (most recent call last):\n', '  File "C:\\ProgramData\\Anaconda3\\lib\\site-packages\\ScopeFoundry\\measurement.py", line 273, in _on_display_update_timer\n    self.update_display()\n', '  File "C:\\LabPrograms\\Python\\ProChipJoystick\\SyncreadoutTriggerJoystickCounterMeasurement.py", line 354, in update_display\n    self.pump_hw.settings[\'set_saved_pressure\']=self.joystick_hw.joystick_dev.get_button_values(Y)\n', '  File "C:\\ProgramData\\Anaconda3\\lib\\site-packages\\ScopeFoundry\\logged_quantity.py", line 1153, in __setitem__\n    self._logged_quantities[key].update_value(item)\n', '  File "C:\\ProgramData\\Anaconda3\\lib\\site-packages\\ScopeFoundry\\logged_quantity.py", line 241, in update_value\n    self.hardware_set_func(self.val)\n', '  File "C:\\LabPrograms\\Python\\FluigentHardwareUpdated\\PumpHardware.py", line 118, in setting_saved_pressure\n    self.settings["set_pressure_3"] = self.saved_pressures[2]\n', 'IndexError: list index out of range\n']
2020-03-03T11:48:19|ERROR|SyncreadoutTriggerJoystickCounterMeasurement|SyncreadoutTriggerJoystickCounterMeasurement Failed to update figure1: list index out of range. ['Traceback (most recent call last):\n', '  File "C:\\ProgramData\\Anaconda3\\lib\\site-packages\\ScopeFoundry\\measurement.py", line 273, in _on_display_update_timer\n    self.update_display()\n', '  File "C:\\LabPrograms\\Python\\ProChipJoystick\\SyncreadoutTriggerJoystickCounterMeasurement.py", line 354, in update_display\n    self.pump_hw.settings[\'set_saved_pressure\']=self.joystick_hw.joystick_dev.get_button_values(Y)\n', '  File "C:\\ProgramData\\Anaconda3\\lib\\site-packages\\ScopeFoundry\\logged_quantity.py", line 1153, in __setitem__\n    self._logged_quantities[key].update_value(item)\n', '  File "C:\\ProgramData\\Anaconda3\\lib\\site-packages\\ScopeFoundry\\logged_quantity.py", line 241, in update_value\n    self.hardware_set_func(self.val)\n', '  File "C:\\LabPrograms\\Python\\FluigentHardwareUpdated\\PumpHardware.py", line 118, in setting_saved_pressure\n    self.settings["set_pressure_3"] = self.saved_pressures[2]\n', 'IndexError: list index out of range\n']
2020-03-03T11:49:21|CRITICAL|root|Unhandled exception:Traceback (most recent call last):
  File "C:\ProgramData\Anaconda3\lib\site-packages\ScopeFoundry\measurement.py", line 25, in run
    self.measurement._thread_run()
  File "C:\ProgramData\Anaconda3\lib\site-packages\ScopeFoundry\measurement.py", line 179, in _thread_run
    self.run()
  File "C:\LabPrograms\Python\ProChipJoystick\SyncreadoutTriggerJoystickCounterMeasurement.py", line 243, in run
    frameA = self.camera.hamamatsu.getRequiredFrame(self.camera.hamamatsu.buffer_index-1)[0]
  File "C:\LabPrograms\Python\Hamamatsu_ScopeFoundry\CameraDevice.py", line 1284, in getRequiredFrame
    hc_data.copyData(paramlock.buf)
  File "C:\LabPrograms\Python\Hamamatsu_ScopeFoundry\CameraDevice.py", line 309, in copyData
    ctypes.memmove(self.np_array.ctypes.data, address, self.size) #copies self.size bytes from address into self.np_array.ctyps.data
OSError: exception: access violation reading 0x0000000000000000

