2020-03-03T11:00:01|CRITICAL|root|Unhandled exception:Traceback (most recent call last):
  File "C:\ProgramData\Anaconda3\lib\site-packages\ScopeFoundry\logged_quantity.py", line 241, in update_value
    self.hardware_set_func(self.val)
  File "C:\LabPrograms\Python\FluigentHardwareUpdated\PumpHardware.py", line 139, in saving_pressure_3
    self.saved_pressures[2] = self.set_pressure_3.val
IndexError: list assignment index out of range

2020-03-03T11:00:01|CRITICAL|root|Unhandled exception:Traceback (most recent call last):
  File "C:\ProgramData\Anaconda3\lib\site-packages\ScopeFoundry\logged_quantity.py", line 241, in update_value
    self.hardware_set_func(self.val)
  File "C:\LabPrograms\Python\FluigentHardwareUpdated\PumpHardware.py", line 146, in saving_pressure_4
    self.saved_pressures[3] = self.set_pressure_4.val
IndexError: list assignment index out of range

2020-03-03T11:00:34|CRITICAL|root|Unhandled exception:Traceback (most recent call last):
  File "C:\ProgramData\Anaconda3\lib\site-packages\ScopeFoundry\logged_quantity.py", line 241, in update_value
    self.hardware_set_func(self.val)
TypeError: setting_saved_pressure() takes 1 positional argument but 2 were given

2020-03-03T11:00:42|CRITICAL|root|Unhandled exception:Traceback (most recent call last):
  File "C:\ProgramData\Anaconda3\lib\site-packages\ScopeFoundry\logged_quantity.py", line 241, in update_value
    self.hardware_set_func(self.val)
TypeError: setting_saved_pressure() takes 1 positional argument but 2 were given

2020-03-03T11:00:43|CRITICAL|root|Unhandled exception:Traceback (most recent call last):
  File "C:\ProgramData\Anaconda3\lib\site-packages\ScopeFoundry\logged_quantity.py", line 241, in update_value
    self.hardware_set_func(self.val)
TypeError: setting_saved_pressure() takes 1 positional argument but 2 were given

2020-03-03T11:00:45|CRITICAL|root|Unhandled exception:Traceback (most recent call last):
  File "C:\ProgramData\Anaconda3\lib\site-packages\ScopeFoundry\logged_quantity.py", line 241, in update_value
    self.hardware_set_func(self.val)
TypeError: setting_saved_pressure() takes 1 positional argument but 2 were given

2020-03-03T11:00:47|CRITICAL|root|Unhandled exception:Traceback (most recent call last):
  File "C:\ProgramData\Anaconda3\lib\site-packages\ScopeFoundry\logged_quantity.py", line 241, in update_value
    self.hardware_set_func(self.val)
TypeError: setting_saved_pressure() takes 1 positional argument but 2 were given

2020-03-03T11:00:47|CRITICAL|root|Unhandled exception:Traceback (most recent call last):
  File "C:\ProgramData\Anaconda3\lib\site-packages\ScopeFoundry\logged_quantity.py", line 241, in update_value
    self.hardware_set_func(self.val)
TypeError: setting_saved_pressure() takes 1 positional argument but 2 were given

2020-03-03T11:00:59|CRITICAL|root|Unhandled exception:Traceback (most recent call last):
  File "C:\ProgramData\Anaconda3\lib\site-packages\ScopeFoundry\logged_quantity.py", line 241, in update_value
    self.hardware_set_func(self.val)
TypeError: setting_saved_pressure() takes 1 positional argument but 2 were given

2020-03-03T11:01:01|CRITICAL|root|Unhandled exception:Traceback (most recent call last):
  File "C:\ProgramData\Anaconda3\lib\site-packages\ScopeFoundry\logged_quantity.py", line 241, in update_value
    self.hardware_set_func(self.val)
TypeError: setting_saved_pressure() takes 1 positional argument but 2 were given

2020-03-03T11:01:02|CRITICAL|root|Unhandled exception:Traceback (most recent call last):
  File "C:\ProgramData\Anaconda3\lib\site-packages\ScopeFoundry\logged_quantity.py", line 241, in update_value
    self.hardware_set_func(self.val)
TypeError: setting_saved_pressure() takes 1 positional argument but 2 were given

2020-03-03T11:01:02|CRITICAL|root|Unhandled exception:Traceback (most recent call last):
  File "C:\ProgramData\Anaconda3\lib\site-packages\ScopeFoundry\logged_quantity.py", line 241, in update_value
    self.hardware_set_func(self.val)
TypeError: setting_saved_pressure() takes 1 positional argument but 2 were given

2020-03-03T11:01:03|CRITICAL|root|Unhandled exception:Traceback (most recent call last):
  File "C:\ProgramData\Anaconda3\lib\site-packages\ScopeFoundry\logged_quantity.py", line 241, in update_value
    self.hardware_set_func(self.val)
TypeError: setting_saved_pressure() takes 1 positional argument but 2 were given

