2019-12-16T19:18:26|CRITICAL|root|Unhandled exception:Traceback (most recent call last):
  File "C:\LabPrograms\Python\Microscopes\ProChipMicroscopeJoystick\ProChipJoystickApp.py", line 25, in <module>
    app = ProChipJoystickApp(sys.argv)
  File "C:\LabPrograms\Python\BaseMicroscopeModified_ScopeFoundry\BaseMicroscopeAppModified.py", line 16, in __init__
    super().__init__(*kwds) # *kwds is needed since in the main we pass as argument sys.argv. Without
  File "C:\ProgramData\Anaconda3\lib\site-packages\ScopeFoundry\base_app.py", line 332, in __init__
    self.setup()
  File "C:\LabPrograms\Python\Microscopes\ProChipMicroscopeJoystick\ProChipJoystickApp.py", line 20, in setup
    self.add_measurement(HamamatsuMeasurement(self))
  File "C:\ProgramData\Anaconda3\lib\site-packages\ScopeFoundry\base_app.py", line 636, in add_measurement
    assert not measure.name in self.measurements.keys()
AssertionError

