2020-02-06T11:52:23|CRITICAL|root|Unhandled exception:Traceback (most recent call last):
  File "C:\LabPrograms\Python\Microscopes\ProChipMicroscopeJoystick\ProChipJoystickApp.py", line 25, in <module>
    app = ProChipJoystickApp(sys.argv)
  File "C:\LabPrograms\Python\BaseMicroscopeModified_ScopeFoundry\BaseMicroscopeAppModified.py", line 16, in __init__
    super().__init__(*kwds) # *kwds is needed since in the main we pass as argument sys.argv. Without
  File "C:\ProgramData\Anaconda3\lib\site-packages\ScopeFoundry\base_app.py", line 332, in __init__
    self.setup()
  File "C:\LabPrograms\Python\Microscopes\ProChipMicroscopeJoystick\ProChipJoystickApp.py", line 16, in setup
    super().setup()
  File "C:\LabPrograms\Python\DAQ_Laser_Camera\Laser_DAQ_Camera_App.py", line 25, in setup
    from DAQ_Laser_Camera.SyncreadoutTriggerCounterMeasurement import SyncreadoutTriggerCounterMeasurement
  File "C:\LabPrograms\Python\DAQ_Laser_Camera\SyncreadoutTriggerCounterMeasurement.py", line 4, in <module>
    from SyncreadoutTriggerMeasurement import SyncreadoutTriggerMeasurement
ModuleNotFoundError: No module named 'SyncreadoutTriggerMeasurement'

